[2025-04-07T18:45:56.944+0000] {local_task_job_runner.py:123} INFO - ::group::Pre task execution logs
[2025-04-07T18:45:56.969+0000] {taskinstance.py:2613} INFO - Dependencies all met for dep_context=non-requeueable deps ti=<TaskInstance: GCP_ingestion_green.upload_to_gcs scheduled__2019-02-02T06:00:00+00:00 [queued]>
[2025-04-07T18:45:56.980+0000] {taskinstance.py:2613} INFO - Dependencies all met for dep_context=requeueable deps ti=<TaskInstance: GCP_ingestion_green.upload_to_gcs scheduled__2019-02-02T06:00:00+00:00 [queued]>
[2025-04-07T18:45:56.981+0000] {taskinstance.py:2866} INFO - Starting attempt 4 of 13
[2025-04-07T18:45:57.000+0000] {taskinstance.py:2889} INFO - Executing <Task(PythonOperator): upload_to_gcs> on 2019-02-02 06:00:00+00:00
[2025-04-07T18:45:57.009+0000] {standard_task_runner.py:72} INFO - Started process 14083 to run task
[2025-04-07T18:45:57.016+0000] {standard_task_runner.py:104} INFO - Running: ['***', 'tasks', 'run', 'GCP_ingestion_green', 'upload_to_gcs', 'scheduled__2019-02-02T06:00:00+00:00', '--job-id', '30', '--raw', '--subdir', 'DAGS_FOLDER/data_ingestion_gcp_green.py', '--cfg-path', '/tmp/tmpx77tj22e']
[2025-04-07T18:45:57.021+0000] {standard_task_runner.py:105} INFO - Job 30: Subtask upload_to_gcs
[2025-04-07T18:45:57.113+0000] {task_command.py:467} INFO - Running <TaskInstance: GCP_ingestion_green.upload_to_gcs scheduled__2019-02-02T06:00:00+00:00 [running]> on host ca240955ca52
[2025-04-07T18:45:57.551+0000] {taskinstance.py:3132} INFO - Exporting env vars: AIRFLOW_CTX_DAG_OWNER='***' AIRFLOW_CTX_DAG_ID='GCP_ingestion_green' AIRFLOW_CTX_TASK_ID='upload_to_gcs' AIRFLOW_CTX_EXECUTION_DATE='2019-02-02T06:00:00+00:00' AIRFLOW_CTX_TRY_NUMBER='4' AIRFLOW_CTX_DAG_RUN_ID='scheduled__2019-02-02T06:00:00+00:00'
[2025-04-07T18:45:57.553+0000] {taskinstance.py:731} INFO - ::endgroup::
[2025-04-07T18:45:57.586+0000] {connection.py:277} WARNING - Connection schemes (type: google_cloud_platform) shall not contain '_' according to RFC3986.
[2025-04-07T18:45:57.589+0000] {base.py:84} INFO - Retrieving connection 'gcp-***'
[2025-04-07T18:45:57.591+0000] {taskinstance.py:3311} ERROR - Task failed with exception
Traceback (most recent call last):
  File "/home/airflow/.local/lib/python3.8/site-packages/airflow/models/taskinstance.py", line 767, in _execute_task
    result = _execute_callable(context=context, **execute_callable_kwargs)
  File "/home/airflow/.local/lib/python3.8/site-packages/airflow/models/taskinstance.py", line 733, in _execute_callable
    return ExecutionCallableRunner(
  File "/home/airflow/.local/lib/python3.8/site-packages/airflow/utils/operator_helpers.py", line 252, in run
    return self.func(*args, **kwargs)
  File "/home/airflow/.local/lib/python3.8/site-packages/airflow/models/baseoperator.py", line 422, in wrapper
    return func(self, *args, **kwargs)
  File "/home/airflow/.local/lib/python3.8/site-packages/airflow/operators/python.py", line 238, in execute
    return_value = self.execute_callable()
  File "/home/airflow/.local/lib/python3.8/site-packages/airflow/operators/python.py", line 256, in execute_callable
    return runner.run(*self.op_args, **self.op_kwargs)
  File "/home/airflow/.local/lib/python3.8/site-packages/airflow/utils/operator_helpers.py", line 252, in run
    return self.func(*args, **kwargs)
  File "/opt/airflow/dags/data_ingestion_gcp_green.py", line 65, in upload_to_gcs
    hook.upload(
  File "/home/airflow/.local/lib/python3.8/site-packages/airflow/providers/google/cloud/hooks/gcs.py", line 528, in upload
    client = self.get_conn()
  File "/home/airflow/.local/lib/python3.8/site-packages/airflow/providers/google/cloud/hooks/gcs.py", line 173, in get_conn
    credentials=self.get_credentials(), client_info=CLIENT_INFO, project=self.project_id
  File "/home/airflow/.local/lib/python3.8/site-packages/airflow/providers/google/common/hooks/base_google.py", line 363, in get_credentials
    credentials, _ = self.get_credentials_and_project_id()
  File "/home/airflow/.local/lib/python3.8/site-packages/airflow/providers/google/common/hooks/base_google.py", line 335, in get_credentials_and_project_id
    credentials, project_id = get_credentials_and_project_id(
  File "/home/airflow/.local/lib/python3.8/site-packages/airflow/providers/google/cloud/utils/credentials_provider.py", line 411, in get_credentials_and_project_id
    return _CredentialProvider(*args, **kwargs).get_credentials_and_project()
  File "/home/airflow/.local/lib/python3.8/site-packages/airflow/providers/google/cloud/utils/credentials_provider.py", line 257, in get_credentials_and_project
    credentials, project_id = self._get_credentials_using_key_path()
  File "/home/airflow/.local/lib/python3.8/site-packages/airflow/providers/google/cloud/utils/credentials_provider.py", line 315, in _get_credentials_using_key_path
    credentials = google.oauth2.service_account.Credentials.from_service_account_file(
  File "/home/airflow/.local/lib/python3.8/site-packages/google/oauth2/service_account.py", line 260, in from_service_account_file
    info, signer = _service_account_info.from_filename(
  File "/home/airflow/.local/lib/python3.8/site-packages/google/auth/_service_account_info.py", line 78, in from_filename
    with io.open(filename, "r", encoding="utf-8") as json_file:
FileNotFoundError: [Errno 2] No such file or directory: '/home/jivagomenezes/00-dev/01-Projects/01-Data-Engineer/01-Active/02-zoomcamp-datatalks/2_Workflow-Orchestration-AirFlow/airflow/google/zoomcamp-airflow-456109-4622775015f7.json'
[2025-04-07T18:45:57.610+0000] {taskinstance.py:1225} INFO - Marking task as UP_FOR_RETRY. dag_id=GCP_ingestion_green, task_id=upload_to_gcs, run_id=scheduled__2019-02-02T06:00:00+00:00, execution_date=20190202T060000, start_date=20250407T184556, end_date=20250407T184557
[2025-04-07T18:45:57.634+0000] {taskinstance.py:340} INFO - ::group::Post task execution logs
[2025-04-07T18:45:57.635+0000] {standard_task_runner.py:124} ERROR - Failed to execute job 30 for task upload_to_gcs ([Errno 2] No such file or directory: '/home/jivagomenezes/00-dev/01-Projects/01-Data-Engineer/01-Active/02-zoomcamp-datatalks/2_Workflow-Orchestration-AirFlow/airflow/google/zoomcamp-airflow-456109-4622775015f7.json'; 14083)
Traceback (most recent call last):
  File "/home/airflow/.local/lib/python3.8/site-packages/airflow/task/task_runner/standard_task_runner.py", line 117, in _start_by_fork
    ret = args.func(args, dag=self.dag)
  File "/home/airflow/.local/lib/python3.8/site-packages/airflow/cli/cli_config.py", line 49, in command
    return func(*args, **kwargs)
  File "/home/airflow/.local/lib/python3.8/site-packages/airflow/utils/cli.py", line 116, in wrapper
    return f(*args, **kwargs)
  File "/home/airflow/.local/lib/python3.8/site-packages/airflow/cli/commands/task_command.py", line 483, in task_run
    task_return_code = _run_task_by_selected_method(args, _dag, ti)
  File "/home/airflow/.local/lib/python3.8/site-packages/airflow/cli/commands/task_command.py", line 256, in _run_task_by_selected_method
    return _run_raw_task(args, ti)
  File "/home/airflow/.local/lib/python3.8/site-packages/airflow/cli/commands/task_command.py", line 341, in _run_raw_task
    return ti._run_raw_task(
  File "/home/airflow/.local/lib/python3.8/site-packages/airflow/utils/session.py", line 97, in wrapper
    return func(*args, session=session, **kwargs)
  File "/home/airflow/.local/lib/python3.8/site-packages/airflow/models/taskinstance.py", line 3005, in _run_raw_task
    return _run_raw_task(
  File "/home/airflow/.local/lib/python3.8/site-packages/airflow/models/taskinstance.py", line 273, in _run_raw_task
    TaskInstance._execute_task_with_callbacks(
  File "/home/airflow/.local/lib/python3.8/site-packages/airflow/models/taskinstance.py", line 3159, in _execute_task_with_callbacks
    result = self._execute_task(context, task_orig)
  File "/home/airflow/.local/lib/python3.8/site-packages/airflow/models/taskinstance.py", line 3183, in _execute_task
    return _execute_task(self, context, task_orig)
  File "/home/airflow/.local/lib/python3.8/site-packages/airflow/models/taskinstance.py", line 767, in _execute_task
    result = _execute_callable(context=context, **execute_callable_kwargs)
  File "/home/airflow/.local/lib/python3.8/site-packages/airflow/models/taskinstance.py", line 733, in _execute_callable
    return ExecutionCallableRunner(
  File "/home/airflow/.local/lib/python3.8/site-packages/airflow/utils/operator_helpers.py", line 252, in run
    return self.func(*args, **kwargs)
  File "/home/airflow/.local/lib/python3.8/site-packages/airflow/models/baseoperator.py", line 422, in wrapper
    return func(self, *args, **kwargs)
  File "/home/airflow/.local/lib/python3.8/site-packages/airflow/operators/python.py", line 238, in execute
    return_value = self.execute_callable()
  File "/home/airflow/.local/lib/python3.8/site-packages/airflow/operators/python.py", line 256, in execute_callable
    return runner.run(*self.op_args, **self.op_kwargs)
  File "/home/airflow/.local/lib/python3.8/site-packages/airflow/utils/operator_helpers.py", line 252, in run
    return self.func(*args, **kwargs)
  File "/opt/airflow/dags/data_ingestion_gcp_green.py", line 65, in upload_to_gcs
    hook.upload(
  File "/home/airflow/.local/lib/python3.8/site-packages/airflow/providers/google/cloud/hooks/gcs.py", line 528, in upload
    client = self.get_conn()
  File "/home/airflow/.local/lib/python3.8/site-packages/airflow/providers/google/cloud/hooks/gcs.py", line 173, in get_conn
    credentials=self.get_credentials(), client_info=CLIENT_INFO, project=self.project_id
  File "/home/airflow/.local/lib/python3.8/site-packages/airflow/providers/google/common/hooks/base_google.py", line 363, in get_credentials
    credentials, _ = self.get_credentials_and_project_id()
  File "/home/airflow/.local/lib/python3.8/site-packages/airflow/providers/google/common/hooks/base_google.py", line 335, in get_credentials_and_project_id
    credentials, project_id = get_credentials_and_project_id(
  File "/home/airflow/.local/lib/python3.8/site-packages/airflow/providers/google/cloud/utils/credentials_provider.py", line 411, in get_credentials_and_project_id
    return _CredentialProvider(*args, **kwargs).get_credentials_and_project()
  File "/home/airflow/.local/lib/python3.8/site-packages/airflow/providers/google/cloud/utils/credentials_provider.py", line 257, in get_credentials_and_project
    credentials, project_id = self._get_credentials_using_key_path()
  File "/home/airflow/.local/lib/python3.8/site-packages/airflow/providers/google/cloud/utils/credentials_provider.py", line 315, in _get_credentials_using_key_path
    credentials = google.oauth2.service_account.Credentials.from_service_account_file(
  File "/home/airflow/.local/lib/python3.8/site-packages/google/oauth2/service_account.py", line 260, in from_service_account_file
    info, signer = _service_account_info.from_filename(
  File "/home/airflow/.local/lib/python3.8/site-packages/google/auth/_service_account_info.py", line 78, in from_filename
    with io.open(filename, "r", encoding="utf-8") as json_file:
FileNotFoundError: [Errno 2] No such file or directory: '/home/jivagomenezes/00-dev/01-Projects/01-Data-Engineer/01-Active/02-zoomcamp-datatalks/2_Workflow-Orchestration-AirFlow/airflow/google/zoomcamp-airflow-456109-4622775015f7.json'
[2025-04-07T18:45:57.682+0000] {local_task_job_runner.py:266} INFO - Task exited with return code 1
[2025-04-07T18:45:57.717+0000] {taskinstance.py:3895} INFO - 0 downstream tasks scheduled from follow-on schedule check
[2025-04-07T18:45:57.721+0000] {local_task_job_runner.py:245} INFO - ::endgroup::
